2021-11-22 14:44:32,381_opmysql.py[line:81]_ERROR (1045, "Access denied for user 'root1'@'localhost' (using password: YES)")
Traceback (most recent call last):
  File "D:/PycharmProjects/Interface_Project/study/mysql_operate/opmysql.py", line 57, in __init__
    cursorclass=pymysql.cursors.DictCursor)
  File "C:\Users\CHENGUANGTAO\AppData\Local\Programs\Python\Python37\lib\site-packages\pymysql\connections.py", line 353, in __init__
    self.connect()
  File "C:\Users\CHENGUANGTAO\AppData\Local\Programs\Python\Python37\lib\site-packages\pymysql\connections.py", line 633, in connect
    self._request_authentication()
  File "C:\Users\CHENGUANGTAO\AppData\Local\Programs\Python\Python37\lib\site-packages\pymysql\connections.py", line 932, in _request_authentication
    auth_packet = _auth.caching_sha2_password_auth(self, auth_packet)
  File "C:\Users\CHENGUANGTAO\AppData\Local\Programs\Python\Python37\lib\site-packages\pymysql\_auth.py", line 266, in caching_sha2_password_auth
    pkt = _roundtrip(conn, data)
  File "C:\Users\CHENGUANGTAO\AppData\Local\Programs\Python\Python37\lib\site-packages\pymysql\_auth.py", line 120, in _roundtrip
    pkt = conn._read_packet()
  File "C:\Users\CHENGUANGTAO\AppData\Local\Programs\Python\Python37\lib\site-packages\pymysql\connections.py", line 725, in _read_packet
    packet.raise_for_error()
  File "C:\Users\CHENGUANGTAO\AppData\Local\Programs\Python\Python37\lib\site-packages\pymysql\protocol.py", line 221, in raise_for_error
    err.raise_mysql_exception(self._data)
  File "C:\Users\CHENGUANGTAO\AppData\Local\Programs\Python\Python37\lib\site-packages\pymysql\err.py", line 143, in raise_mysql_exception
    raise errorclass(errno, errval)
pymysql.err.OperationalError: (1045, "Access denied for user 'root1'@'localhost' (using password: YES)")
2021-11-22 14:44:42,567_opmysql.py[line:81]_ERROR (1045, "Access denied for user 'root1'@'localhost' (using password: YES)")
Traceback (most recent call last):
  File "D:/PycharmProjects/Interface_Project/study/mysql_operate/opmysql.py", line 57, in __init__
    cursorclass=pymysql.cursors.DictCursor)
  File "C:\Users\CHENGUANGTAO\AppData\Local\Programs\Python\Python37\lib\site-packages\pymysql\connections.py", line 353, in __init__
    self.connect()
  File "C:\Users\CHENGUANGTAO\AppData\Local\Programs\Python\Python37\lib\site-packages\pymysql\connections.py", line 633, in connect
    self._request_authentication()
  File "C:\Users\CHENGUANGTAO\AppData\Local\Programs\Python\Python37\lib\site-packages\pymysql\connections.py", line 932, in _request_authentication
    auth_packet = _auth.caching_sha2_password_auth(self, auth_packet)
  File "C:\Users\CHENGUANGTAO\AppData\Local\Programs\Python\Python37\lib\site-packages\pymysql\_auth.py", line 266, in caching_sha2_password_auth
    pkt = _roundtrip(conn, data)
  File "C:\Users\CHENGUANGTAO\AppData\Local\Programs\Python\Python37\lib\site-packages\pymysql\_auth.py", line 120, in _roundtrip
    pkt = conn._read_packet()
  File "C:\Users\CHENGUANGTAO\AppData\Local\Programs\Python\Python37\lib\site-packages\pymysql\connections.py", line 725, in _read_packet
    packet.raise_for_error()
  File "C:\Users\CHENGUANGTAO\AppData\Local\Programs\Python\Python37\lib\site-packages\pymysql\protocol.py", line 221, in raise_for_error
    err.raise_mysql_exception(self._data)
  File "C:\Users\CHENGUANGTAO\AppData\Local\Programs\Python\Python37\lib\site-packages\pymysql\err.py", line 143, in raise_mysql_exception
    raise errorclass(errno, errval)
pymysql.err.OperationalError: (1045, "Access denied for user 'root1'@'localhost' (using password: YES)")
2021-11-22 14:44:50,034_opmysql.py[line:81]_ERROR (1045, "Access denied for user 'root1'@'localhost' (using password: YES)")
Traceback (most recent call last):
  File "D:/PycharmProjects/Interface_Project/study/mysql_operate/opmysql.py", line 57, in __init__
    cursorclass=pymysql.cursors.DictCursor)
  File "C:\Users\CHENGUANGTAO\AppData\Local\Programs\Python\Python37\lib\site-packages\pymysql\connections.py", line 353, in __init__
    self.connect()
  File "C:\Users\CHENGUANGTAO\AppData\Local\Programs\Python\Python37\lib\site-packages\pymysql\connections.py", line 633, in connect
    self._request_authentication()
  File "C:\Users\CHENGUANGTAO\AppData\Local\Programs\Python\Python37\lib\site-packages\pymysql\connections.py", line 932, in _request_authentication
    auth_packet = _auth.caching_sha2_password_auth(self, auth_packet)
  File "C:\Users\CHENGUANGTAO\AppData\Local\Programs\Python\Python37\lib\site-packages\pymysql\_auth.py", line 266, in caching_sha2_password_auth
    pkt = _roundtrip(conn, data)
  File "C:\Users\CHENGUANGTAO\AppData\Local\Programs\Python\Python37\lib\site-packages\pymysql\_auth.py", line 120, in _roundtrip
    pkt = conn._read_packet()
  File "C:\Users\CHENGUANGTAO\AppData\Local\Programs\Python\Python37\lib\site-packages\pymysql\connections.py", line 725, in _read_packet
    packet.raise_for_error()
  File "C:\Users\CHENGUANGTAO\AppData\Local\Programs\Python\Python37\lib\site-packages\pymysql\protocol.py", line 221, in raise_for_error
    err.raise_mysql_exception(self._data)
  File "C:\Users\CHENGUANGTAO\AppData\Local\Programs\Python\Python37\lib\site-packages\pymysql\err.py", line 143, in raise_mysql_exception
    raise errorclass(errno, errval)
pymysql.err.OperationalError: (1045, "Access denied for user 'root1'@'localhost' (using password: YES)")
2021-11-22 14:44:58,805_opmysql.py[line:81]_ERROR (1045, "Access denied for user 'root1'@'localhost' (using password: YES)")
Traceback (most recent call last):
  File "D:/PycharmProjects/Interface_Project/study/mysql_operate/opmysql.py", line 57, in __init__
    cursorclass=pymysql.cursors.DictCursor)
  File "C:\Users\CHENGUANGTAO\AppData\Local\Programs\Python\Python37\lib\site-packages\pymysql\connections.py", line 353, in __init__
    self.connect()
  File "C:\Users\CHENGUANGTAO\AppData\Local\Programs\Python\Python37\lib\site-packages\pymysql\connections.py", line 633, in connect
    self._request_authentication()
  File "C:\Users\CHENGUANGTAO\AppData\Local\Programs\Python\Python37\lib\site-packages\pymysql\connections.py", line 932, in _request_authentication
    auth_packet = _auth.caching_sha2_password_auth(self, auth_packet)
  File "C:\Users\CHENGUANGTAO\AppData\Local\Programs\Python\Python37\lib\site-packages\pymysql\_auth.py", line 266, in caching_sha2_password_auth
    pkt = _roundtrip(conn, data)
  File "C:\Users\CHENGUANGTAO\AppData\Local\Programs\Python\Python37\lib\site-packages\pymysql\_auth.py", line 120, in _roundtrip
    pkt = conn._read_packet()
  File "C:\Users\CHENGUANGTAO\AppData\Local\Programs\Python\Python37\lib\site-packages\pymysql\connections.py", line 725, in _read_packet
    packet.raise_for_error()
  File "C:\Users\CHENGUANGTAO\AppData\Local\Programs\Python\Python37\lib\site-packages\pymysql\protocol.py", line 221, in raise_for_error
    err.raise_mysql_exception(self._data)
  File "C:\Users\CHENGUANGTAO\AppData\Local\Programs\Python\Python37\lib\site-packages\pymysql\err.py", line 143, in raise_mysql_exception
    raise errorclass(errno, errval)
pymysql.err.OperationalError: (1045, "Access denied for user 'root1'@'localhost' (using password: YES)")
2021-11-22 14:45:05,643_opmysql.py[line:81]_ERROR (1045, "Access denied for user 'root1'@'localhost' (using password: YES)")
Traceback (most recent call last):
  File "D:/PycharmProjects/Interface_Project/study/mysql_operate/opmysql.py", line 57, in __init__
    cursorclass=pymysql.cursors.DictCursor)
  File "C:\Users\CHENGUANGTAO\AppData\Local\Programs\Python\Python37\lib\site-packages\pymysql\connections.py", line 353, in __init__
    self.connect()
  File "C:\Users\CHENGUANGTAO\AppData\Local\Programs\Python\Python37\lib\site-packages\pymysql\connections.py", line 633, in connect
    self._request_authentication()
  File "C:\Users\CHENGUANGTAO\AppData\Local\Programs\Python\Python37\lib\site-packages\pymysql\connections.py", line 932, in _request_authentication
    auth_packet = _auth.caching_sha2_password_auth(self, auth_packet)
  File "C:\Users\CHENGUANGTAO\AppData\Local\Programs\Python\Python37\lib\site-packages\pymysql\_auth.py", line 266, in caching_sha2_password_auth
    pkt = _roundtrip(conn, data)
  File "C:\Users\CHENGUANGTAO\AppData\Local\Programs\Python\Python37\lib\site-packages\pymysql\_auth.py", line 120, in _roundtrip
    pkt = conn._read_packet()
  File "C:\Users\CHENGUANGTAO\AppData\Local\Programs\Python\Python37\lib\site-packages\pymysql\connections.py", line 725, in _read_packet
    packet.raise_for_error()
  File "C:\Users\CHENGUANGTAO\AppData\Local\Programs\Python\Python37\lib\site-packages\pymysql\protocol.py", line 221, in raise_for_error
    err.raise_mysql_exception(self._data)
  File "C:\Users\CHENGUANGTAO\AppData\Local\Programs\Python\Python37\lib\site-packages\pymysql\err.py", line 143, in raise_mysql_exception
    raise errorclass(errno, errval)
pymysql.err.OperationalError: (1045, "Access denied for user 'root1'@'localhost' (using password: YES)")
2021-11-22 14:46:45,388_opmysql.py[line:76]_ERROR (1064, "You have an error in your SQL syntax; check the manual that corresponds to your MySQL server version for the right syntax to use near '1 from config_total' at line 1")
Traceback (most recent call last):
  File "D:/PycharmProjects/Interface_Project/study/mysql_operate/opmysql.py", line 86, in op_sql
    self.cur.execute(condition)
  File "C:\Users\CHENGUANGTAO\AppData\Local\Programs\Python\Python37\lib\site-packages\pymysql\cursors.py", line 148, in execute
    result = self._query(query)
  File "C:\Users\CHENGUANGTAO\AppData\Local\Programs\Python\Python37\lib\site-packages\pymysql\cursors.py", line 310, in _query
    conn.query(q)
  File "C:\Users\CHENGUANGTAO\AppData\Local\Programs\Python\Python37\lib\site-packages\pymysql\connections.py", line 548, in query
    self._affected_rows = self._read_query_result(unbuffered=unbuffered)
  File "C:\Users\CHENGUANGTAO\AppData\Local\Programs\Python\Python37\lib\site-packages\pymysql\connections.py", line 775, in _read_query_result
    result.read()
  File "C:\Users\CHENGUANGTAO\AppData\Local\Programs\Python\Python37\lib\site-packages\pymysql\connections.py", line 1156, in read
    first_packet = self.connection._read_packet()
  File "C:\Users\CHENGUANGTAO\AppData\Local\Programs\Python\Python37\lib\site-packages\pymysql\connections.py", line 725, in _read_packet
    packet.raise_for_error()
  File "C:\Users\CHENGUANGTAO\AppData\Local\Programs\Python\Python37\lib\site-packages\pymysql\protocol.py", line 221, in raise_for_error
    err.raise_mysql_exception(self._data)
  File "C:\Users\CHENGUANGTAO\AppData\Local\Programs\Python\Python37\lib\site-packages\pymysql\err.py", line 143, in raise_mysql_exception
    raise errorclass(errno, errval)
pymysql.err.ProgrammingError: (1064, "You have an error in your SQL syntax; check the manual that corresponds to your MySQL server version for the right syntax to use near '1 from config_total' at line 1")
2021-11-22 14:51:32,662_opmysql.py[line:82]_ERROR (1064, "You have an error in your SQL syntax; check the manual that corresponds to your MySQL server version for the right syntax to use near '* from config_total where id=1' at line 1")
Traceback (most recent call last):
  File "D:/PycharmProjects/Interface_Project/study/mysql_operate/opmysql.py", line 92, in op_sql
    self.cur.execute(condition)
  File "C:\Users\CHENGUANGTAO\AppData\Local\Programs\Python\Python37\lib\site-packages\pymysql\cursors.py", line 148, in execute
    result = self._query(query)
  File "C:\Users\CHENGUANGTAO\AppData\Local\Programs\Python\Python37\lib\site-packages\pymysql\cursors.py", line 310, in _query
    conn.query(q)
  File "C:\Users\CHENGUANGTAO\AppData\Local\Programs\Python\Python37\lib\site-packages\pymysql\connections.py", line 548, in query
    self._affected_rows = self._read_query_result(unbuffered=unbuffered)
  File "C:\Users\CHENGUANGTAO\AppData\Local\Programs\Python\Python37\lib\site-packages\pymysql\connections.py", line 775, in _read_query_result
    result.read()
  File "C:\Users\CHENGUANGTAO\AppData\Local\Programs\Python\Python37\lib\site-packages\pymysql\connections.py", line 1156, in read
    first_packet = self.connection._read_packet()
  File "C:\Users\CHENGUANGTAO\AppData\Local\Programs\Python\Python37\lib\site-packages\pymysql\connections.py", line 725, in _read_packet
    packet.raise_for_error()
  File "C:\Users\CHENGUANGTAO\AppData\Local\Programs\Python\Python37\lib\site-packages\pymysql\protocol.py", line 221, in raise_for_error
    err.raise_mysql_exception(self._data)
  File "C:\Users\CHENGUANGTAO\AppData\Local\Programs\Python\Python37\lib\site-packages\pymysql\err.py", line 143, in raise_mysql_exception
    raise errorclass(errno, errval)
pymysql.err.ProgrammingError: (1064, "You have an error in your SQL syntax; check the manual that corresponds to your MySQL server version for the right syntax to use near '* from config_total where id=1' at line 1")
2021-11-22 14:51:41,704_opmysql.py[line:82]_ERROR (1064, "You have an error in your SQL syntax; check the manual that corresponds to your MySQL server version for the right syntax to use near '* from config_total where id==1' at line 1")
Traceback (most recent call last):
  File "D:/PycharmProjects/Interface_Project/study/mysql_operate/opmysql.py", line 92, in op_sql
    self.cur.execute(condition)
  File "C:\Users\CHENGUANGTAO\AppData\Local\Programs\Python\Python37\lib\site-packages\pymysql\cursors.py", line 148, in execute
    result = self._query(query)
  File "C:\Users\CHENGUANGTAO\AppData\Local\Programs\Python\Python37\lib\site-packages\pymysql\cursors.py", line 310, in _query
    conn.query(q)
  File "C:\Users\CHENGUANGTAO\AppData\Local\Programs\Python\Python37\lib\site-packages\pymysql\connections.py", line 548, in query
    self._affected_rows = self._read_query_result(unbuffered=unbuffered)
  File "C:\Users\CHENGUANGTAO\AppData\Local\Programs\Python\Python37\lib\site-packages\pymysql\connections.py", line 775, in _read_query_result
    result.read()
  File "C:\Users\CHENGUANGTAO\AppData\Local\Programs\Python\Python37\lib\site-packages\pymysql\connections.py", line 1156, in read
    first_packet = self.connection._read_packet()
  File "C:\Users\CHENGUANGTAO\AppData\Local\Programs\Python\Python37\lib\site-packages\pymysql\connections.py", line 725, in _read_packet
    packet.raise_for_error()
  File "C:\Users\CHENGUANGTAO\AppData\Local\Programs\Python\Python37\lib\site-packages\pymysql\protocol.py", line 221, in raise_for_error
    err.raise_mysql_exception(self._data)
  File "C:\Users\CHENGUANGTAO\AppData\Local\Programs\Python\Python37\lib\site-packages\pymysql\err.py", line 143, in raise_mysql_exception
    raise errorclass(errno, errval)
pymysql.err.ProgrammingError: (1064, "You have an error in your SQL syntax; check the manual that corresponds to your MySQL server version for the right syntax to use near '* from config_total where id==1' at line 1")
2021-11-22 14:51:49,575_opmysql.py[line:82]_ERROR (1064, "You have an error in your SQL syntax; check the manual that corresponds to your MySQL server version for the right syntax to use near '* from config_total which id==1' at line 1")
Traceback (most recent call last):
  File "D:/PycharmProjects/Interface_Project/study/mysql_operate/opmysql.py", line 92, in op_sql
    self.cur.execute(condition)
  File "C:\Users\CHENGUANGTAO\AppData\Local\Programs\Python\Python37\lib\site-packages\pymysql\cursors.py", line 148, in execute
    result = self._query(query)
  File "C:\Users\CHENGUANGTAO\AppData\Local\Programs\Python\Python37\lib\site-packages\pymysql\cursors.py", line 310, in _query
    conn.query(q)
  File "C:\Users\CHENGUANGTAO\AppData\Local\Programs\Python\Python37\lib\site-packages\pymysql\connections.py", line 548, in query
    self._affected_rows = self._read_query_result(unbuffered=unbuffered)
  File "C:\Users\CHENGUANGTAO\AppData\Local\Programs\Python\Python37\lib\site-packages\pymysql\connections.py", line 775, in _read_query_result
    result.read()
  File "C:\Users\CHENGUANGTAO\AppData\Local\Programs\Python\Python37\lib\site-packages\pymysql\connections.py", line 1156, in read
    first_packet = self.connection._read_packet()
  File "C:\Users\CHENGUANGTAO\AppData\Local\Programs\Python\Python37\lib\site-packages\pymysql\connections.py", line 725, in _read_packet
    packet.raise_for_error()
  File "C:\Users\CHENGUANGTAO\AppData\Local\Programs\Python\Python37\lib\site-packages\pymysql\protocol.py", line 221, in raise_for_error
    err.raise_mysql_exception(self._data)
  File "C:\Users\CHENGUANGTAO\AppData\Local\Programs\Python\Python37\lib\site-packages\pymysql\err.py", line 143, in raise_mysql_exception
    raise errorclass(errno, errval)
pymysql.err.ProgrammingError: (1064, "You have an error in your SQL syntax; check the manual that corresponds to your MySQL server version for the right syntax to use near '* from config_total which id==1' at line 1")
2021-11-22 14:51:51,759_opmysql.py[line:82]_ERROR (1064, "You have an error in your SQL syntax; check the manual that corresponds to your MySQL server version for the right syntax to use near '* from config_total which id=1' at line 1")
Traceback (most recent call last):
  File "D:/PycharmProjects/Interface_Project/study/mysql_operate/opmysql.py", line 92, in op_sql
    self.cur.execute(condition)
  File "C:\Users\CHENGUANGTAO\AppData\Local\Programs\Python\Python37\lib\site-packages\pymysql\cursors.py", line 148, in execute
    result = self._query(query)
  File "C:\Users\CHENGUANGTAO\AppData\Local\Programs\Python\Python37\lib\site-packages\pymysql\cursors.py", line 310, in _query
    conn.query(q)
  File "C:\Users\CHENGUANGTAO\AppData\Local\Programs\Python\Python37\lib\site-packages\pymysql\connections.py", line 548, in query
    self._affected_rows = self._read_query_result(unbuffered=unbuffered)
  File "C:\Users\CHENGUANGTAO\AppData\Local\Programs\Python\Python37\lib\site-packages\pymysql\connections.py", line 775, in _read_query_result
    result.read()
  File "C:\Users\CHENGUANGTAO\AppData\Local\Programs\Python\Python37\lib\site-packages\pymysql\connections.py", line 1156, in read
    first_packet = self.connection._read_packet()
  File "C:\Users\CHENGUANGTAO\AppData\Local\Programs\Python\Python37\lib\site-packages\pymysql\connections.py", line 725, in _read_packet
    packet.raise_for_error()
  File "C:\Users\CHENGUANGTAO\AppData\Local\Programs\Python\Python37\lib\site-packages\pymysql\protocol.py", line 221, in raise_for_error
    err.raise_mysql_exception(self._data)
  File "C:\Users\CHENGUANGTAO\AppData\Local\Programs\Python\Python37\lib\site-packages\pymysql\err.py", line 143, in raise_mysql_exception
    raise errorclass(errno, errval)
pymysql.err.ProgrammingError: (1064, "You have an error in your SQL syntax; check the manual that corresponds to your MySQL server version for the right syntax to use near '* from config_total which id=1' at line 1")
2021-11-22 14:51:57,389_opmysql.py[line:82]_ERROR (1064, "You have an error in your SQL syntax; check the manual that corresponds to your MySQL server version for the right syntax to use near '* from config_total where id=1' at line 1")
Traceback (most recent call last):
  File "D:/PycharmProjects/Interface_Project/study/mysql_operate/opmysql.py", line 92, in op_sql
    self.cur.execute(condition)
  File "C:\Users\CHENGUANGTAO\AppData\Local\Programs\Python\Python37\lib\site-packages\pymysql\cursors.py", line 148, in execute
    result = self._query(query)
  File "C:\Users\CHENGUANGTAO\AppData\Local\Programs\Python\Python37\lib\site-packages\pymysql\cursors.py", line 310, in _query
    conn.query(q)
  File "C:\Users\CHENGUANGTAO\AppData\Local\Programs\Python\Python37\lib\site-packages\pymysql\connections.py", line 548, in query
    self._affected_rows = self._read_query_result(unbuffered=unbuffered)
  File "C:\Users\CHENGUANGTAO\AppData\Local\Programs\Python\Python37\lib\site-packages\pymysql\connections.py", line 775, in _read_query_result
    result.read()
  File "C:\Users\CHENGUANGTAO\AppData\Local\Programs\Python\Python37\lib\site-packages\pymysql\connections.py", line 1156, in read
    first_packet = self.connection._read_packet()
  File "C:\Users\CHENGUANGTAO\AppData\Local\Programs\Python\Python37\lib\site-packages\pymysql\connections.py", line 725, in _read_packet
    packet.raise_for_error()
  File "C:\Users\CHENGUANGTAO\AppData\Local\Programs\Python\Python37\lib\site-packages\pymysql\protocol.py", line 221, in raise_for_error
    err.raise_mysql_exception(self._data)
  File "C:\Users\CHENGUANGTAO\AppData\Local\Programs\Python\Python37\lib\site-packages\pymysql\err.py", line 143, in raise_mysql_exception
    raise errorclass(errno, errval)
pymysql.err.ProgrammingError: (1064, "You have an error in your SQL syntax; check the manual that corresponds to your MySQL server version for the right syntax to use near '* from config_total where id=1' at line 1")
2021-11-22 14:59:49,931_opmysql.py[line:82]_ERROR (1064, "You have an error in your SQL syntax; check the manual that corresponds to your MySQL server version for the right syntax to use near '*' at line 1")
Traceback (most recent call last):
  File "D:/PycharmProjects/Interface_Project/study/mysql_operate/opmysql.py", line 92, in op_sql
    self.cur.execute(condition)
  File "C:\Users\CHENGUANGTAO\AppData\Local\Programs\Python\Python37\lib\site-packages\pymysql\cursors.py", line 148, in execute
    result = self._query(query)
  File "C:\Users\CHENGUANGTAO\AppData\Local\Programs\Python\Python37\lib\site-packages\pymysql\cursors.py", line 310, in _query
    conn.query(q)
  File "C:\Users\CHENGUANGTAO\AppData\Local\Programs\Python\Python37\lib\site-packages\pymysql\connections.py", line 548, in query
    self._affected_rows = self._read_query_result(unbuffered=unbuffered)
  File "C:\Users\CHENGUANGTAO\AppData\Local\Programs\Python\Python37\lib\site-packages\pymysql\connections.py", line 775, in _read_query_result
    result.read()
  File "C:\Users\CHENGUANGTAO\AppData\Local\Programs\Python\Python37\lib\site-packages\pymysql\connections.py", line 1156, in read
    first_packet = self.connection._read_packet()
  File "C:\Users\CHENGUANGTAO\AppData\Local\Programs\Python\Python37\lib\site-packages\pymysql\connections.py", line 725, in _read_packet
    packet.raise_for_error()
  File "C:\Users\CHENGUANGTAO\AppData\Local\Programs\Python\Python37\lib\site-packages\pymysql\protocol.py", line 221, in raise_for_error
    err.raise_mysql_exception(self._data)
  File "C:\Users\CHENGUANGTAO\AppData\Local\Programs\Python\Python37\lib\site-packages\pymysql\err.py", line 143, in raise_mysql_exception
    raise errorclass(errno, errval)
pymysql.err.ProgrammingError: (1064, "You have an error in your SQL syntax; check the manual that corresponds to your MySQL server version for the right syntax to use near '*' at line 1")
